<?xml version="1.0" ?>
<robot name="bicycle">

  <!-- Define the world link -->
  <link name="world"/>

  <!-- Define the base link and joint -->
  <link name="base_link"/>
  <joint name="base_joint" type="fixed">
    <parent link="world"/>
    <child link="base_link"/>
  </joint>

  <!-- Define the front wheel link and joint -->
  <link name="front_wheel_link">
    <visual>
      <origin rpy="0 0 0" xyz="0 0 0"/>
      <geometry>
        <cylinder length="0.01" radius="0.3"/>
      </geometry>
    </visual>
  </link>
  <joint name="front_wheel_joint" type="continuous">
    <parent link="base_link"/>
    <child link="front_wheel_link"/>
    <origin xyz="0 0 0.5"/>
    <axis xyz="1 0 0"/>
  </joint>

  <!-- Define the back wheel link and joint -->
  <link name="back_wheel_link">
    <visual>
      <origin rpy="0 0 0" xyz="0 0 0"/>
      <geometry>
        <cylinder length="0.01" radius="0.3"/>
      </geometry>
    </visual>
  </link>
  <joint name="back_wheel_joint" type="continuous">
    <parent link="base_link"/>
    <child link="back_wheel_link"/>
    <origin xyz="-0.9 0 0.5"/>
    <axis xyz="0 1 0"/>
  </joint>

  <!-- Define the frame link and joint -->
  <link name="frame_link">
    <visual>
      <origin rpy="0 0 0" xyz="0 0 0"/>
      <geometry>
        <box size="1.8 0.1 0.5"/>
      </geometry>
    </visual>
  </link>
  <joint name="frame_joint" type="revolute">
    <parent link="base_link"/>
    <child link="frame_link"/>
    <origin xyz="0 0 0.7"/>
    <axis xyz="0 1 0"/>
  </joint>

  <!-- Define the handlebar link and joint -->
  <link name="handlebar_link">
    <visual>
      <origin rpy="0 0 0" xyz="0 0 0"/>
      <geometry>
        <box size="0.1 1.2 0.1"/>
      </geometry>
    </visual>
  </link>
  <joint name="handlebar_joint" type="revolute">
    <parent link="frame_link"/>
    <child link="handlebar_link"/>
    <origin xyz="0.9 0 1"/>
    <axis xyz="0 0 1"/>
  </joint>

</robot>

